[2024-07-07 04:20:07,397: INFO: _internal: [31m[1mWARNING: This is a development server. Do not use it in a production deployment. Use a production WSGI server instead.[0m
 * Running on all addresses (0.0.0.0)
 * Running on http://127.0.0.1:8080
 * Running on http://192.168.186.236:8080]
[2024-07-07 04:20:07,398: INFO: _internal: [33mPress CTRL+C to quit[0m]
[2024-07-07 04:20:19,193: INFO: _internal: 127.0.0.1 - - [07/Jul/2024 04:20:19] "GET / HTTP/1.1" 200 -]
[2024-07-07 04:20:21,367: INFO: _internal: 127.0.0.1 - - [07/Jul/2024 04:20:21] "[33mGET /favicon.ico HTTP/1.1[0m" 404 -]
[2024-07-07 04:20:37,781: INFO: _internal: 127.0.0.1 - - [07/Jul/2024 04:20:37] "GET / HTTP/1.1" 200 -]
[2024-07-07 04:20:40,744: INFO: _internal: 127.0.0.1 - - [07/Jul/2024 04:20:40] "GET / HTTP/1.1" 200 -]
[2024-07-07 04:26:45,487: INFO: _internal: [31m[1mWARNING: This is a development server. Do not use it in a production deployment. Use a production WSGI server instead.[0m
 * Running on all addresses (0.0.0.0)
 * Running on http://127.0.0.1:8080
 * Running on http://192.168.186.236:8080]
[2024-07-07 04:26:45,488: INFO: _internal: [33mPress CTRL+C to quit[0m]
[2024-07-07 04:26:52,111: ERROR: app: Exception on / [GET]]
Traceback (most recent call last):
  File "/opt/anaconda3/envs/mlproj/lib/python3.8/site-packages/flask/app.py", line 2190, in wsgi_app
    response = self.full_dispatch_request()
  File "/opt/anaconda3/envs/mlproj/lib/python3.8/site-packages/flask/app.py", line 1486, in full_dispatch_request
    rv = self.handle_user_exception(e)
  File "/opt/anaconda3/envs/mlproj/lib/python3.8/site-packages/flask_cors/extension.py", line 178, in wrapped_function
    return cors_after_request(app.make_response(f(*args, **kwargs)))
  File "/opt/anaconda3/envs/mlproj/lib/python3.8/site-packages/flask/app.py", line 1484, in full_dispatch_request
    rv = self.dispatch_request()
  File "/opt/anaconda3/envs/mlproj/lib/python3.8/site-packages/flask/app.py", line 1469, in dispatch_request
    return self.ensure_sync(self.view_functions[rule.endpoint])(**view_args)
  File "/opt/anaconda3/envs/mlproj/lib/python3.8/site-packages/flask_cors/decorator.py", line 130, in wrapped_function
    resp = make_response(f(*args, **kwargs))
  File "app.py", line 27, in home
    return render_template(clientPath)
  File "/opt/anaconda3/envs/mlproj/lib/python3.8/site-packages/flask/templating.py", line 150, in render_template
    template = app.jinja_env.get_or_select_template(template_name_or_list)
  File "/opt/anaconda3/envs/mlproj/lib/python3.8/site-packages/jinja2/environment.py", line 1087, in get_or_select_template
    return self.select_template(template_name_or_list, parent, globals)
  File "/opt/anaconda3/envs/mlproj/lib/python3.8/site-packages/jinja2/environment.py", line 1058, in select_template
    for name in names:
TypeError: 'PosixPath' object is not iterable
[2024-07-07 04:26:52,131: INFO: _internal: 127.0.0.1 - - [07/Jul/2024 04:26:52] "[35m[1mGET / HTTP/1.1[0m" 500 -]
[2024-07-07 04:28:37,075: INFO: _internal: [31m[1mWARNING: This is a development server. Do not use it in a production deployment. Use a production WSGI server instead.[0m
 * Running on all addresses (0.0.0.0)
 * Running on http://127.0.0.1:8080
 * Running on http://192.168.186.236:8080]
[2024-07-07 04:28:37,075: INFO: _internal: [33mPress CTRL+C to quit[0m]
[2024-07-07 04:28:44,513: ERROR: app: Exception on / [GET]]
Traceback (most recent call last):
  File "/opt/anaconda3/envs/mlproj/lib/python3.8/site-packages/flask/app.py", line 2190, in wsgi_app
    response = self.full_dispatch_request()
  File "/opt/anaconda3/envs/mlproj/lib/python3.8/site-packages/flask/app.py", line 1486, in full_dispatch_request
    rv = self.handle_user_exception(e)
  File "/opt/anaconda3/envs/mlproj/lib/python3.8/site-packages/flask_cors/extension.py", line 178, in wrapped_function
    return cors_after_request(app.make_response(f(*args, **kwargs)))
  File "/opt/anaconda3/envs/mlproj/lib/python3.8/site-packages/flask/app.py", line 1484, in full_dispatch_request
    rv = self.dispatch_request()
  File "/opt/anaconda3/envs/mlproj/lib/python3.8/site-packages/flask/app.py", line 1469, in dispatch_request
    return self.ensure_sync(self.view_functions[rule.endpoint])(**view_args)
  File "/opt/anaconda3/envs/mlproj/lib/python3.8/site-packages/flask_cors/decorator.py", line 130, in wrapped_function
    resp = make_response(f(*args, **kwargs))
  File "app.py", line 27, in home
    return render_template(str(clientPath))
  File "/opt/anaconda3/envs/mlproj/lib/python3.8/site-packages/flask/templating.py", line 150, in render_template
    template = app.jinja_env.get_or_select_template(template_name_or_list)
  File "/opt/anaconda3/envs/mlproj/lib/python3.8/site-packages/jinja2/environment.py", line 1084, in get_or_select_template
    return self.get_template(template_name_or_list, parent, globals)
  File "/opt/anaconda3/envs/mlproj/lib/python3.8/site-packages/jinja2/environment.py", line 1013, in get_template
    return self._load_template(name, globals)
  File "/opt/anaconda3/envs/mlproj/lib/python3.8/site-packages/jinja2/environment.py", line 972, in _load_template
    template = self.loader.load(self, name, self.make_globals(globals))
  File "/opt/anaconda3/envs/mlproj/lib/python3.8/site-packages/jinja2/loaders.py", line 126, in load
    source, filename, uptodate = self.get_source(environment, name)
  File "/opt/anaconda3/envs/mlproj/lib/python3.8/site-packages/flask/templating.py", line 64, in get_source
    return self._get_source_fast(environment, template)
  File "/opt/anaconda3/envs/mlproj/lib/python3.8/site-packages/flask/templating.py", line 98, in _get_source_fast
    raise TemplateNotFound(template)
jinja2.exceptions.TemplateNotFound: client/index.html
[2024-07-07 04:28:44,536: INFO: _internal: 127.0.0.1 - - [07/Jul/2024 04:28:44] "[35m[1mGET / HTTP/1.1[0m" 500 -]
[2024-07-07 04:28:48,369: ERROR: app: Exception on / [GET]]
Traceback (most recent call last):
  File "/opt/anaconda3/envs/mlproj/lib/python3.8/site-packages/flask/app.py", line 2190, in wsgi_app
    response = self.full_dispatch_request()
  File "/opt/anaconda3/envs/mlproj/lib/python3.8/site-packages/flask/app.py", line 1486, in full_dispatch_request
    rv = self.handle_user_exception(e)
  File "/opt/anaconda3/envs/mlproj/lib/python3.8/site-packages/flask_cors/extension.py", line 178, in wrapped_function
    return cors_after_request(app.make_response(f(*args, **kwargs)))
  File "/opt/anaconda3/envs/mlproj/lib/python3.8/site-packages/flask/app.py", line 1484, in full_dispatch_request
    rv = self.dispatch_request()
  File "/opt/anaconda3/envs/mlproj/lib/python3.8/site-packages/flask/app.py", line 1469, in dispatch_request
    return self.ensure_sync(self.view_functions[rule.endpoint])(**view_args)
  File "/opt/anaconda3/envs/mlproj/lib/python3.8/site-packages/flask_cors/decorator.py", line 130, in wrapped_function
    resp = make_response(f(*args, **kwargs))
  File "app.py", line 27, in home
    return render_template(str(clientPath))
  File "/opt/anaconda3/envs/mlproj/lib/python3.8/site-packages/flask/templating.py", line 150, in render_template
    template = app.jinja_env.get_or_select_template(template_name_or_list)
  File "/opt/anaconda3/envs/mlproj/lib/python3.8/site-packages/jinja2/environment.py", line 1084, in get_or_select_template
    return self.get_template(template_name_or_list, parent, globals)
  File "/opt/anaconda3/envs/mlproj/lib/python3.8/site-packages/jinja2/environment.py", line 1013, in get_template
    return self._load_template(name, globals)
  File "/opt/anaconda3/envs/mlproj/lib/python3.8/site-packages/jinja2/environment.py", line 972, in _load_template
    template = self.loader.load(self, name, self.make_globals(globals))
  File "/opt/anaconda3/envs/mlproj/lib/python3.8/site-packages/jinja2/loaders.py", line 126, in load
    source, filename, uptodate = self.get_source(environment, name)
  File "/opt/anaconda3/envs/mlproj/lib/python3.8/site-packages/flask/templating.py", line 64, in get_source
    return self._get_source_fast(environment, template)
  File "/opt/anaconda3/envs/mlproj/lib/python3.8/site-packages/flask/templating.py", line 98, in _get_source_fast
    raise TemplateNotFound(template)
jinja2.exceptions.TemplateNotFound: client/index.html
[2024-07-07 04:28:48,371: INFO: _internal: 127.0.0.1 - - [07/Jul/2024 04:28:48] "[35m[1mGET / HTTP/1.1[0m" 500 -]
[2024-07-07 04:32:42,644: INFO: _internal: 127.0.0.1 - - [07/Jul/2024 04:32:42] "GET / HTTP/1.1" 200 -]
[2024-07-07 04:32:42,720: INFO: _internal: 127.0.0.1 - - [07/Jul/2024 04:32:42] "[33mGET /style.css HTTP/1.1[0m" 404 -]
[2024-07-07 04:32:42,722: INFO: _internal: 127.0.0.1 - - [07/Jul/2024 04:32:42] "[33mGET /app.js HTTP/1.1[0m" 404 -]
[2024-07-07 04:32:51,580: INFO: _internal: 127.0.0.1 - - [07/Jul/2024 04:32:51] "GET / HTTP/1.1" 200 -]
[2024-07-07 04:32:51,642: INFO: _internal: 127.0.0.1 - - [07/Jul/2024 04:32:51] "[33mGET /style.css HTTP/1.1[0m" 404 -]
[2024-07-07 04:32:51,647: INFO: _internal: 127.0.0.1 - - [07/Jul/2024 04:32:51] "[33mGET /app.js HTTP/1.1[0m" 404 -]
[2024-07-07 04:36:37,512: INFO: _internal: 127.0.0.1 - - [07/Jul/2024 04:36:37] "GET / HTTP/1.1" 200 -]
[2024-07-07 04:36:37,609: INFO: _internal: 127.0.0.1 - - [07/Jul/2024 04:36:37] "[33mGET /style.css HTTP/1.1[0m" 404 -]
[2024-07-07 04:36:37,612: INFO: _internal: 127.0.0.1 - - [07/Jul/2024 04:36:37] "[33mGET /app.js HTTP/1.1[0m" 404 -]
[2024-07-07 04:36:42,997: INFO: _internal: 127.0.0.1 - - [07/Jul/2024 04:36:42] "GET / HTTP/1.1" 200 -]
[2024-07-07 04:36:43,284: INFO: _internal: 127.0.0.1 - - [07/Jul/2024 04:36:43] "[33mGET /style.css HTTP/1.1[0m" 404 -]
[2024-07-07 04:36:43,406: INFO: _internal: 127.0.0.1 - - [07/Jul/2024 04:36:43] "[33mGET /app.js HTTP/1.1[0m" 404 -]
[2024-07-07 04:37:49,563: INFO: _internal: 127.0.0.1 - - [07/Jul/2024 04:37:49] "GET / HTTP/1.1" 200 -]
[2024-07-07 04:37:49,626: INFO: _internal: 127.0.0.1 - - [07/Jul/2024 04:37:49] "[33mGET /app.js HTTP/1.1[0m" 404 -]
[2024-07-07 04:37:49,630: INFO: _internal: 127.0.0.1 - - [07/Jul/2024 04:37:49] "[33mGET /style.css HTTP/1.1[0m" 404 -]
[2024-07-07 04:37:53,459: INFO: _internal: 127.0.0.1 - - [07/Jul/2024 04:37:53] "GET / HTTP/1.1" 200 -]
[2024-07-07 04:37:53,539: INFO: _internal: 127.0.0.1 - - [07/Jul/2024 04:37:53] "[33mGET /style.css HTTP/1.1[0m" 404 -]
[2024-07-07 04:37:53,542: INFO: _internal: 127.0.0.1 - - [07/Jul/2024 04:37:53] "[33mGET /app.js HTTP/1.1[0m" 404 -]
[2024-07-07 04:38:03,157: INFO: _internal: 127.0.0.1 - - [07/Jul/2024 04:38:03] "GET / HTTP/1.1" 200 -]
[2024-07-07 04:38:03,213: INFO: _internal: 127.0.0.1 - - [07/Jul/2024 04:38:03] "[33mGET /style.css HTTP/1.1[0m" 404 -]
[2024-07-07 04:38:03,216: INFO: _internal: 127.0.0.1 - - [07/Jul/2024 04:38:03] "[33mGET /app.js HTTP/1.1[0m" 404 -]
[2024-07-07 04:38:05,645: INFO: _internal: 127.0.0.1 - - [07/Jul/2024 04:38:05] "GET / HTTP/1.1" 200 -]
[2024-07-07 04:38:05,670: INFO: _internal: 127.0.0.1 - - [07/Jul/2024 04:38:05] "[33mGET /style.css HTTP/1.1[0m" 404 -]
[2024-07-07 04:38:05,684: INFO: _internal: 127.0.0.1 - - [07/Jul/2024 04:38:05] "[33mGET /app.js HTTP/1.1[0m" 404 -]
[2024-07-07 04:39:05,393: INFO: _internal: [31m[1mWARNING: This is a development server. Do not use it in a production deployment. Use a production WSGI server instead.[0m
 * Running on all addresses (0.0.0.0)
 * Running on http://127.0.0.1:8080
 * Running on http://192.168.186.236:8080]
[2024-07-07 04:39:05,394: INFO: _internal: [33mPress CTRL+C to quit[0m]
[2024-07-07 04:39:16,358: INFO: _internal: 127.0.0.1 - - [07/Jul/2024 04:39:16] "GET / HTTP/1.1" 200 -]
[2024-07-07 04:39:16,434: INFO: _internal: 127.0.0.1 - - [07/Jul/2024 04:39:16] "GET /static/js/app.js HTTP/1.1" 200 -]
[2024-07-07 04:39:16,455: INFO: _internal: 127.0.0.1 - - [07/Jul/2024 04:39:16] "GET /static/css/style.css HTTP/1.1" 200 -]
[2024-07-07 05:29:39,532: INFO: _internal: 127.0.0.1 - - [07/Jul/2024 05:29:39] "[36mGET /static/css/style.css HTTP/1.1[0m" 304 -]
[2024-07-07 05:32:48,167: INFO: _internal: 127.0.0.1 - - [07/Jul/2024 05:32:48] "GET / HTTP/1.1" 200 -]
[2024-07-07 05:32:48,303: INFO: _internal: 127.0.0.1 - - [07/Jul/2024 05:32:48] "[36mGET /static/css/style.css HTTP/1.1[0m" 304 -]
[2024-07-07 05:32:48,305: INFO: _internal: 127.0.0.1 - - [07/Jul/2024 05:32:48] "[36mGET /static/js/app.js HTTP/1.1[0m" 304 -]
[2024-07-07 05:33:46,539: INFO: _internal: 127.0.0.1 - - [07/Jul/2024 05:33:46] "GET / HTTP/1.1" 200 -]
[2024-07-07 05:33:46,615: INFO: _internal: 127.0.0.1 - - [07/Jul/2024 05:33:46] "[36mGET /static/css/style.css HTTP/1.1[0m" 304 -]
[2024-07-07 05:33:46,616: INFO: _internal: 127.0.0.1 - - [07/Jul/2024 05:33:46] "GET /static/js/app.js HTTP/1.1" 200 -]
[2024-07-07 05:34:01,008: INFO: _internal: 127.0.0.1 - - [07/Jul/2024 05:34:01] "GET / HTTP/1.1" 200 -]
[2024-07-07 05:34:01,069: INFO: _internal: 127.0.0.1 - - [07/Jul/2024 05:34:01] "[36mGET /static/css/style.css HTTP/1.1[0m" 304 -]
[2024-07-07 05:34:01,076: INFO: _internal: 127.0.0.1 - - [07/Jul/2024 05:34:01] "[36mGET /static/js/app.js HTTP/1.1[0m" 304 -]
[2024-07-07 05:54:34,794: INFO: _internal: 127.0.0.1 - - [07/Jul/2024 05:54:34] "GET / HTTP/1.1" 200 -]
[2024-07-07 05:54:34,971: INFO: _internal: 127.0.0.1 - - [07/Jul/2024 05:54:34] "[36mGET /static/css/style.css HTTP/1.1[0m" 304 -]
[2024-07-07 05:54:34,975: INFO: _internal: 127.0.0.1 - - [07/Jul/2024 05:54:34] "GET /static/js/app.js HTTP/1.1" 200 -]
[2024-07-07 06:01:09,868: INFO: _internal: 127.0.0.1 - - [07/Jul/2024 06:01:09] "GET / HTTP/1.1" 200 -]
[2024-07-07 06:01:09,989: INFO: _internal: 127.0.0.1 - - [07/Jul/2024 06:01:09] "[36mGET /static/css/style.css HTTP/1.1[0m" 304 -]
[2024-07-07 06:01:10,003: INFO: _internal: 127.0.0.1 - - [07/Jul/2024 06:01:10] "GET /static/js/app.js HTTP/1.1" 200 -]
[2024-07-07 06:01:24,159: INFO: _internal: 127.0.0.1 - - [07/Jul/2024 06:01:24] "[33mPOST /process_image HTTP/1.1[0m" 404 -]
[2024-07-07 06:05:17,937: INFO: _internal: [31m[1mWARNING: This is a development server. Do not use it in a production deployment. Use a production WSGI server instead.[0m
 * Running on all addresses (0.0.0.0)
 * Running on http://127.0.0.1:8080
 * Running on http://192.168.186.236:8080]
[2024-07-07 06:05:17,938: INFO: _internal: [33mPress CTRL+C to quit[0m]
[2024-07-07 06:05:27,100: INFO: _internal: 127.0.0.1 - - [07/Jul/2024 06:05:27] "GET / HTTP/1.1" 200 -]
[2024-07-07 06:05:27,212: INFO: _internal: 127.0.0.1 - - [07/Jul/2024 06:05:27] "[36mGET /static/css/style.css HTTP/1.1[0m" 304 -]
[2024-07-07 06:05:27,213: INFO: _internal: 127.0.0.1 - - [07/Jul/2024 06:05:27] "[36mGET /static/js/app.js HTTP/1.1[0m" 304 -]
[2024-07-07 06:05:39,005: ERROR: app: Exception on /process_image [POST]]
Traceback (most recent call last):
  File "/opt/anaconda3/envs/mlproj/lib/python3.8/site-packages/flask/app.py", line 2190, in wsgi_app
    response = self.full_dispatch_request()
  File "/opt/anaconda3/envs/mlproj/lib/python3.8/site-packages/flask/app.py", line 1486, in full_dispatch_request
    rv = self.handle_user_exception(e)
  File "/opt/anaconda3/envs/mlproj/lib/python3.8/site-packages/flask_cors/extension.py", line 178, in wrapped_function
    return cors_after_request(app.make_response(f(*args, **kwargs)))
  File "/opt/anaconda3/envs/mlproj/lib/python3.8/site-packages/flask/app.py", line 1484, in full_dispatch_request
    rv = self.dispatch_request()
  File "/opt/anaconda3/envs/mlproj/lib/python3.8/site-packages/flask/app.py", line 1469, in dispatch_request
    return self.ensure_sync(self.view_functions[rule.endpoint])(**view_args)
  File "/opt/anaconda3/envs/mlproj/lib/python3.8/site-packages/flask_cors/decorator.py", line 130, in wrapped_function
    resp = make_response(f(*args, **kwargs))
  File "/opt/anaconda3/envs/mlproj/lib/python3.8/site-packages/flask/helpers.py", line 178, in make_response
    return current_app.make_response(args)  # type: ignore
  File "/opt/anaconda3/envs/mlproj/lib/python3.8/site-packages/flask/app.py", line 1801, in make_response
    raise TypeError(
TypeError: The view function for 'process_image' did not return a valid response. The function either returned None or ended without a return statement.
[2024-07-07 06:05:39,074: INFO: _internal: 127.0.0.1 - - [07/Jul/2024 06:05:39] "[35m[1mPOST /process_image HTTP/1.1[0m" 500 -]
[2024-07-07 06:06:51,745: INFO: _internal: [31m[1mWARNING: This is a development server. Do not use it in a production deployment. Use a production WSGI server instead.[0m
 * Running on all addresses (0.0.0.0)
 * Running on http://127.0.0.1:8080
 * Running on http://192.168.186.236:8080]
[2024-07-07 06:06:51,745: INFO: _internal: [33mPress CTRL+C to quit[0m]
[2024-07-07 06:07:07,127: INFO: _internal: 127.0.0.1 - - [07/Jul/2024 06:07:07] "GET / HTTP/1.1" 200 -]
[2024-07-07 06:07:07,226: INFO: _internal: 127.0.0.1 - - [07/Jul/2024 06:07:07] "[36mGET /static/css/style.css HTTP/1.1[0m" 304 -]
[2024-07-07 06:07:07,229: INFO: _internal: 127.0.0.1 - - [07/Jul/2024 06:07:07] "[36mGET /static/js/app.js HTTP/1.1[0m" 304 -]
[2024-07-07 06:07:29,714: ERROR: app: Exception on /process_image [POST]]
Traceback (most recent call last):
  File "/opt/anaconda3/envs/mlproj/lib/python3.8/site-packages/flask/app.py", line 2190, in wsgi_app
    response = self.full_dispatch_request()
  File "/opt/anaconda3/envs/mlproj/lib/python3.8/site-packages/flask/app.py", line 1486, in full_dispatch_request
    rv = self.handle_user_exception(e)
  File "/opt/anaconda3/envs/mlproj/lib/python3.8/site-packages/flask_cors/extension.py", line 178, in wrapped_function
    return cors_after_request(app.make_response(f(*args, **kwargs)))
  File "/opt/anaconda3/envs/mlproj/lib/python3.8/site-packages/flask/app.py", line 1484, in full_dispatch_request
    rv = self.dispatch_request()
  File "/opt/anaconda3/envs/mlproj/lib/python3.8/site-packages/flask/app.py", line 1469, in dispatch_request
    return self.ensure_sync(self.view_functions[rule.endpoint])(**view_args)
  File "/opt/anaconda3/envs/mlproj/lib/python3.8/site-packages/flask_cors/decorator.py", line 130, in wrapped_function
    resp = make_response(f(*args, **kwargs))
  File "app.py", line 43, in process_image
    img = Image.open(file_path)
  File "/opt/anaconda3/envs/mlproj/lib/python3.8/site-packages/PIL/Image.py", line 3339, in open
    raise UnidentifiedImageError(msg)
PIL.UnidentifiedImageError: cannot identify image file '/Users/olatunji/Desktop/CNN Project/dump/v09044g40000cpa7psnog65i2175ni2g.MP4'
[2024-07-07 06:07:29,728: INFO: _internal: 127.0.0.1 - - [07/Jul/2024 06:07:29] "[35m[1mPOST /process_image HTTP/1.1[0m" 500 -]
[2024-07-07 06:07:36,557: INFO: _internal: 127.0.0.1 - - [07/Jul/2024 06:07:36] "GET / HTTP/1.1" 200 -]
[2024-07-07 06:07:36,650: INFO: _internal: 127.0.0.1 - - [07/Jul/2024 06:07:36] "[36mGET /static/js/app.js HTTP/1.1[0m" 304 -]
[2024-07-07 06:07:36,650: INFO: _internal: 127.0.0.1 - - [07/Jul/2024 06:07:36] "[36mGET /static/css/style.css HTTP/1.1[0m" 304 -]
[2024-07-07 06:07:54,442: ERROR: app: Exception on /process_image [POST]]
Traceback (most recent call last):
  File "/opt/anaconda3/envs/mlproj/lib/python3.8/site-packages/flask/app.py", line 2190, in wsgi_app
    response = self.full_dispatch_request()
  File "/opt/anaconda3/envs/mlproj/lib/python3.8/site-packages/flask/app.py", line 1486, in full_dispatch_request
    rv = self.handle_user_exception(e)
  File "/opt/anaconda3/envs/mlproj/lib/python3.8/site-packages/flask_cors/extension.py", line 178, in wrapped_function
    return cors_after_request(app.make_response(f(*args, **kwargs)))
  File "/opt/anaconda3/envs/mlproj/lib/python3.8/site-packages/flask/app.py", line 1484, in full_dispatch_request
    rv = self.dispatch_request()
  File "/opt/anaconda3/envs/mlproj/lib/python3.8/site-packages/flask/app.py", line 1469, in dispatch_request
    return self.ensure_sync(self.view_functions[rule.endpoint])(**view_args)
  File "/opt/anaconda3/envs/mlproj/lib/python3.8/site-packages/flask_cors/decorator.py", line 130, in wrapped_function
    resp = make_response(f(*args, **kwargs))
  File "app.py", line 48, in process_image
    model = tf.keras.models.load_model(os.path.join("model", "trained_model.h5"))
  File "/opt/anaconda3/envs/mlproj/lib/python3.8/site-packages/keras/saving/saving_api.py", line 212, in load_model
    return legacy_sm_saving_lib.load_model(
  File "/opt/anaconda3/envs/mlproj/lib/python3.8/site-packages/keras/utils/traceback_utils.py", line 70, in error_handler
    raise e.with_traceback(filtered_tb) from None
  File "/opt/anaconda3/envs/mlproj/lib/python3.8/site-packages/keras/saving/legacy/save.py", line 230, in load_model
    raise IOError(
OSError: No file or directory found at model/trained_model.h5
[2024-07-07 06:07:54,447: INFO: _internal: 127.0.0.1 - - [07/Jul/2024 06:07:54] "[35m[1mPOST /process_image HTTP/1.1[0m" 500 -]
[2024-07-07 06:09:57,294: INFO: _internal: 127.0.0.1 - - [07/Jul/2024 06:09:57] "GET / HTTP/1.1" 200 -]
[2024-07-07 06:09:57,424: INFO: _internal: 127.0.0.1 - - [07/Jul/2024 06:09:57] "[36mGET /static/js/app.js HTTP/1.1[0m" 304 -]
[2024-07-07 06:09:57,426: INFO: _internal: 127.0.0.1 - - [07/Jul/2024 06:09:57] "[36mGET /static/css/style.css HTTP/1.1[0m" 304 -]
[2024-07-07 06:10:04,856: ERROR: app: Exception on /process_image [POST]]
Traceback (most recent call last):
  File "/opt/anaconda3/envs/mlproj/lib/python3.8/site-packages/flask/app.py", line 2190, in wsgi_app
    response = self.full_dispatch_request()
  File "/opt/anaconda3/envs/mlproj/lib/python3.8/site-packages/flask/app.py", line 1486, in full_dispatch_request
    rv = self.handle_user_exception(e)
  File "/opt/anaconda3/envs/mlproj/lib/python3.8/site-packages/flask_cors/extension.py", line 178, in wrapped_function
    return cors_after_request(app.make_response(f(*args, **kwargs)))
  File "/opt/anaconda3/envs/mlproj/lib/python3.8/site-packages/flask/app.py", line 1484, in full_dispatch_request
    rv = self.dispatch_request()
  File "/opt/anaconda3/envs/mlproj/lib/python3.8/site-packages/flask/app.py", line 1469, in dispatch_request
    return self.ensure_sync(self.view_functions[rule.endpoint])(**view_args)
  File "/opt/anaconda3/envs/mlproj/lib/python3.8/site-packages/flask_cors/decorator.py", line 130, in wrapped_function
    resp = make_response(f(*args, **kwargs))
  File "app.py", line 48, in process_image
    model = tf.keras.models.load_model(os.path.join("models", "trained_model.h5"))
  File "/opt/anaconda3/envs/mlproj/lib/python3.8/site-packages/keras/saving/saving_api.py", line 212, in load_model
    return legacy_sm_saving_lib.load_model(
  File "/opt/anaconda3/envs/mlproj/lib/python3.8/site-packages/keras/utils/traceback_utils.py", line 70, in error_handler
    raise e.with_traceback(filtered_tb) from None
  File "/opt/anaconda3/envs/mlproj/lib/python3.8/site-packages/keras/saving/legacy/save.py", line 230, in load_model
    raise IOError(
OSError: No file or directory found at model/trained_model.h5
[2024-07-07 06:10:04,859: INFO: _internal: 127.0.0.1 - - [07/Jul/2024 06:10:04] "[35m[1mPOST /process_image HTTP/1.1[0m" 500 -]
[2024-07-07 06:12:23,581: INFO: _internal: [31m[1mWARNING: This is a development server. Do not use it in a production deployment. Use a production WSGI server instead.[0m
 * Running on all addresses (0.0.0.0)
 * Running on http://127.0.0.1:8080
 * Running on http://192.168.186.236:8080]
[2024-07-07 06:12:23,581: INFO: _internal: [33mPress CTRL+C to quit[0m]
[2024-07-07 06:12:37,046: INFO: _internal: 127.0.0.1 - - [07/Jul/2024 06:12:37] "GET / HTTP/1.1" 200 -]
[2024-07-07 06:12:37,104: INFO: _internal: 127.0.0.1 - - [07/Jul/2024 06:12:37] "[36mGET /static/css/style.css HTTP/1.1[0m" 304 -]
[2024-07-07 06:12:37,107: INFO: _internal: 127.0.0.1 - - [07/Jul/2024 06:12:37] "[36mGET /static/js/app.js HTTP/1.1[0m" 304 -]
[2024-07-07 06:12:53,843: ERROR: app: Exception on /process_image [POST]]
Traceback (most recent call last):
  File "/opt/anaconda3/envs/mlproj/lib/python3.8/site-packages/flask/app.py", line 2190, in wsgi_app
    response = self.full_dispatch_request()
  File "/opt/anaconda3/envs/mlproj/lib/python3.8/site-packages/flask/app.py", line 1486, in full_dispatch_request
    rv = self.handle_user_exception(e)
  File "/opt/anaconda3/envs/mlproj/lib/python3.8/site-packages/flask_cors/extension.py", line 178, in wrapped_function
    return cors_after_request(app.make_response(f(*args, **kwargs)))
  File "/opt/anaconda3/envs/mlproj/lib/python3.8/site-packages/flask/app.py", line 1484, in full_dispatch_request
    rv = self.dispatch_request()
  File "/opt/anaconda3/envs/mlproj/lib/python3.8/site-packages/flask/app.py", line 1469, in dispatch_request
    return self.ensure_sync(self.view_functions[rule.endpoint])(**view_args)
  File "/opt/anaconda3/envs/mlproj/lib/python3.8/site-packages/flask_cors/decorator.py", line 130, in wrapped_function
    resp = make_response(f(*args, **kwargs))
  File "app.py", line 49, in process_image
    result = np.argmax(model.predict(img_array), axis=1)
  File "/opt/anaconda3/envs/mlproj/lib/python3.8/site-packages/keras/utils/traceback_utils.py", line 70, in error_handler
    raise e.with_traceback(filtered_tb) from None
  File "/var/folders/_n/ppng6yzd1vb0pk3s230rdd540000gp/T/__autograph_generated_filemz9dxeub.py", line 15, in tf__predict_function
    retval_ = ag__.converted_call(ag__.ld(step_function), (ag__.ld(self), ag__.ld(iterator)), None, fscope)
ValueError: in user code:

    File "/opt/anaconda3/envs/mlproj/lib/python3.8/site-packages/keras/engine/training.py", line 2169, in predict_function  *
        return step_function(self, iterator)
    File "/opt/anaconda3/envs/mlproj/lib/python3.8/site-packages/keras/engine/training.py", line 2155, in step_function  **
        outputs = model.distribute_strategy.run(run_step, args=(data,))
    File "/opt/anaconda3/envs/mlproj/lib/python3.8/site-packages/keras/engine/training.py", line 2143, in run_step  **
        outputs = model.predict_step(data)
    File "/opt/anaconda3/envs/mlproj/lib/python3.8/site-packages/keras/engine/training.py", line 2111, in predict_step
        return self(x, training=False)
    File "/opt/anaconda3/envs/mlproj/lib/python3.8/site-packages/keras/utils/traceback_utils.py", line 70, in error_handler
        raise e.with_traceback(filtered_tb) from None
    File "/opt/anaconda3/envs/mlproj/lib/python3.8/site-packages/keras/engine/input_spec.py", line 298, in assert_input_compatibility
        raise ValueError(

    ValueError: Input 0 of layer "model" is incompatible with the layer: expected shape=(None, 224, 224, 3), found shape=(None, 224, 224, 4)

[2024-07-07 06:12:53,852: INFO: _internal: 127.0.0.1 - - [07/Jul/2024 06:12:53] "[35m[1mPOST /process_image HTTP/1.1[0m" 500 -]
[2024-07-07 06:18:49,986: INFO: _internal: 127.0.0.1 - - [07/Jul/2024 06:18:49] "GET / HTTP/1.1" 200 -]
[2024-07-07 06:18:50,081: INFO: _internal: 127.0.0.1 - - [07/Jul/2024 06:18:50] "[36mGET /static/css/style.css HTTP/1.1[0m" 304 -]
[2024-07-07 06:18:50,084: INFO: _internal: 127.0.0.1 - - [07/Jul/2024 06:18:50] "GET /static/js/app.js HTTP/1.1" 200 -]
[2024-07-07 06:19:04,992: INFO: _internal: 127.0.0.1 - - [07/Jul/2024 06:19:04] "POST /process_image HTTP/1.1" 200 -]
[2024-07-07 06:20:01,438: ERROR: app: Exception on /process_image [POST]]
Traceback (most recent call last):
  File "/opt/anaconda3/envs/mlproj/lib/python3.8/site-packages/flask/app.py", line 2190, in wsgi_app
    response = self.full_dispatch_request()
  File "/opt/anaconda3/envs/mlproj/lib/python3.8/site-packages/flask/app.py", line 1486, in full_dispatch_request
    rv = self.handle_user_exception(e)
  File "/opt/anaconda3/envs/mlproj/lib/python3.8/site-packages/flask_cors/extension.py", line 178, in wrapped_function
    return cors_after_request(app.make_response(f(*args, **kwargs)))
  File "/opt/anaconda3/envs/mlproj/lib/python3.8/site-packages/flask/app.py", line 1484, in full_dispatch_request
    rv = self.dispatch_request()
  File "/opt/anaconda3/envs/mlproj/lib/python3.8/site-packages/flask/app.py", line 1469, in dispatch_request
    return self.ensure_sync(self.view_functions[rule.endpoint])(**view_args)
  File "/opt/anaconda3/envs/mlproj/lib/python3.8/site-packages/flask_cors/decorator.py", line 130, in wrapped_function
    resp = make_response(f(*args, **kwargs))
  File "app.py", line 49, in process_image
    result = np.argmax(model.predict(img_array), axis=1)
  File "/opt/anaconda3/envs/mlproj/lib/python3.8/site-packages/keras/utils/traceback_utils.py", line 70, in error_handler
    raise e.with_traceback(filtered_tb) from None
  File "/var/folders/_n/ppng6yzd1vb0pk3s230rdd540000gp/T/__autograph_generated_filemz9dxeub.py", line 15, in tf__predict_function
    retval_ = ag__.converted_call(ag__.ld(step_function), (ag__.ld(self), ag__.ld(iterator)), None, fscope)
ValueError: in user code:

    File "/opt/anaconda3/envs/mlproj/lib/python3.8/site-packages/keras/engine/training.py", line 2169, in predict_function  *
        return step_function(self, iterator)
    File "/opt/anaconda3/envs/mlproj/lib/python3.8/site-packages/keras/engine/training.py", line 2155, in step_function  **
        outputs = model.distribute_strategy.run(run_step, args=(data,))
    File "/opt/anaconda3/envs/mlproj/lib/python3.8/site-packages/keras/engine/training.py", line 2143, in run_step  **
        outputs = model.predict_step(data)
    File "/opt/anaconda3/envs/mlproj/lib/python3.8/site-packages/keras/engine/training.py", line 2111, in predict_step
        return self(x, training=False)
    File "/opt/anaconda3/envs/mlproj/lib/python3.8/site-packages/keras/utils/traceback_utils.py", line 70, in error_handler
        raise e.with_traceback(filtered_tb) from None
    File "/opt/anaconda3/envs/mlproj/lib/python3.8/site-packages/keras/engine/input_spec.py", line 298, in assert_input_compatibility
        raise ValueError(

    ValueError: Input 0 of layer "model" is incompatible with the layer: expected shape=(None, 224, 224, 3), found shape=(None, 224, 224, 4)

[2024-07-07 06:20:01,446: INFO: _internal: 127.0.0.1 - - [07/Jul/2024 06:20:01] "[35m[1mPOST /process_image HTTP/1.1[0m" 500 -]
[2024-07-07 06:20:13,888: INFO: _internal: 127.0.0.1 - - [07/Jul/2024 06:20:13] "GET / HTTP/1.1" 200 -]
[2024-07-07 06:20:13,954: INFO: _internal: 127.0.0.1 - - [07/Jul/2024 06:20:13] "[36mGET /static/css/style.css HTTP/1.1[0m" 304 -]
[2024-07-07 06:20:13,955: INFO: _internal: 127.0.0.1 - - [07/Jul/2024 06:20:13] "[36mGET /static/js/app.js HTTP/1.1[0m" 304 -]
[2024-07-07 06:20:28,263: INFO: _internal: 127.0.0.1 - - [07/Jul/2024 06:20:28] "POST /process_image HTTP/1.1" 200 -]
[2024-07-07 06:21:41,668: INFO: _internal: 127.0.0.1 - - [07/Jul/2024 06:21:41] "GET / HTTP/1.1" 200 -]
[2024-07-07 06:21:41,731: INFO: _internal: 127.0.0.1 - - [07/Jul/2024 06:21:41] "[36mGET /static/css/style.css HTTP/1.1[0m" 304 -]
[2024-07-07 06:21:41,737: INFO: _internal: 127.0.0.1 - - [07/Jul/2024 06:21:41] "[36mGET /static/js/app.js HTTP/1.1[0m" 304 -]
[2024-07-07 06:22:55,625: ERROR: app: Exception on /process_image [POST]]
Traceback (most recent call last):
  File "/opt/anaconda3/envs/mlproj/lib/python3.8/site-packages/flask/app.py", line 2190, in wsgi_app
    response = self.full_dispatch_request()
  File "/opt/anaconda3/envs/mlproj/lib/python3.8/site-packages/flask/app.py", line 1486, in full_dispatch_request
    rv = self.handle_user_exception(e)
  File "/opt/anaconda3/envs/mlproj/lib/python3.8/site-packages/flask_cors/extension.py", line 178, in wrapped_function
    return cors_after_request(app.make_response(f(*args, **kwargs)))
  File "/opt/anaconda3/envs/mlproj/lib/python3.8/site-packages/flask/app.py", line 1484, in full_dispatch_request
    rv = self.dispatch_request()
  File "/opt/anaconda3/envs/mlproj/lib/python3.8/site-packages/flask/app.py", line 1469, in dispatch_request
    return self.ensure_sync(self.view_functions[rule.endpoint])(**view_args)
  File "/opt/anaconda3/envs/mlproj/lib/python3.8/site-packages/flask_cors/decorator.py", line 130, in wrapped_function
    resp = make_response(f(*args, **kwargs))
  File "app.py", line 49, in process_image
    result = np.argmax(model.predict(img_array), axis=1)
  File "/opt/anaconda3/envs/mlproj/lib/python3.8/site-packages/keras/utils/traceback_utils.py", line 70, in error_handler
    raise e.with_traceback(filtered_tb) from None
  File "/var/folders/_n/ppng6yzd1vb0pk3s230rdd540000gp/T/__autograph_generated_filemz9dxeub.py", line 15, in tf__predict_function
    retval_ = ag__.converted_call(ag__.ld(step_function), (ag__.ld(self), ag__.ld(iterator)), None, fscope)
ValueError: in user code:

    File "/opt/anaconda3/envs/mlproj/lib/python3.8/site-packages/keras/engine/training.py", line 2169, in predict_function  *
        return step_function(self, iterator)
    File "/opt/anaconda3/envs/mlproj/lib/python3.8/site-packages/keras/engine/training.py", line 2155, in step_function  **
        outputs = model.distribute_strategy.run(run_step, args=(data,))
    File "/opt/anaconda3/envs/mlproj/lib/python3.8/site-packages/keras/engine/training.py", line 2143, in run_step  **
        outputs = model.predict_step(data)
    File "/opt/anaconda3/envs/mlproj/lib/python3.8/site-packages/keras/engine/training.py", line 2111, in predict_step
        return self(x, training=False)
    File "/opt/anaconda3/envs/mlproj/lib/python3.8/site-packages/keras/utils/traceback_utils.py", line 70, in error_handler
        raise e.with_traceback(filtered_tb) from None
    File "/opt/anaconda3/envs/mlproj/lib/python3.8/site-packages/keras/engine/input_spec.py", line 298, in assert_input_compatibility
        raise ValueError(

    ValueError: Input 0 of layer "model" is incompatible with the layer: expected shape=(None, 224, 224, 3), found shape=(None, 224, 224, 4)

[2024-07-07 06:22:55,632: INFO: _internal: 127.0.0.1 - - [07/Jul/2024 06:22:55] "[35m[1mPOST /process_image HTTP/1.1[0m" 500 -]
[2024-07-07 06:26:18,150: INFO: _internal: [31m[1mWARNING: This is a development server. Do not use it in a production deployment. Use a production WSGI server instead.[0m
 * Running on all addresses (0.0.0.0)
 * Running on http://127.0.0.1:8080
 * Running on http://192.168.186.236:8080]
[2024-07-07 06:26:18,151: INFO: _internal: [33mPress CTRL+C to quit[0m]
[2024-07-07 06:26:25,284: INFO: _internal: 127.0.0.1 - - [07/Jul/2024 06:26:25] "GET / HTTP/1.1" 200 -]
[2024-07-07 06:26:25,369: INFO: _internal: 127.0.0.1 - - [07/Jul/2024 06:26:25] "[36mGET /static/css/style.css HTTP/1.1[0m" 304 -]
[2024-07-07 06:26:25,371: INFO: _internal: 127.0.0.1 - - [07/Jul/2024 06:26:25] "[36mGET /static/js/app.js HTTP/1.1[0m" 304 -]
[2024-07-07 06:26:36,269: ERROR: app: Exception on /process_image [POST]]
Traceback (most recent call last):
  File "/opt/anaconda3/envs/mlproj/lib/python3.8/site-packages/flask/app.py", line 2190, in wsgi_app
    response = self.full_dispatch_request()
  File "/opt/anaconda3/envs/mlproj/lib/python3.8/site-packages/flask/app.py", line 1486, in full_dispatch_request
    rv = self.handle_user_exception(e)
  File "/opt/anaconda3/envs/mlproj/lib/python3.8/site-packages/flask_cors/extension.py", line 178, in wrapped_function
    return cors_after_request(app.make_response(f(*args, **kwargs)))
  File "/opt/anaconda3/envs/mlproj/lib/python3.8/site-packages/flask/app.py", line 1484, in full_dispatch_request
    rv = self.dispatch_request()
  File "/opt/anaconda3/envs/mlproj/lib/python3.8/site-packages/flask/app.py", line 1469, in dispatch_request
    return self.ensure_sync(self.view_functions[rule.endpoint])(**view_args)
  File "/opt/anaconda3/envs/mlproj/lib/python3.8/site-packages/flask_cors/decorator.py", line 130, in wrapped_function
    resp = make_response(f(*args, **kwargs))
  File "app.py", line 49, in process_image
    result = np.argmax(model.predict(img_array), axis=1)
  File "/opt/anaconda3/envs/mlproj/lib/python3.8/site-packages/keras/utils/traceback_utils.py", line 70, in error_handler
    raise e.with_traceback(filtered_tb) from None
  File "/var/folders/_n/ppng6yzd1vb0pk3s230rdd540000gp/T/__autograph_generated_file7yyt6tg9.py", line 15, in tf__predict_function
    retval_ = ag__.converted_call(ag__.ld(step_function), (ag__.ld(self), ag__.ld(iterator)), None, fscope)
ValueError: in user code:

    File "/opt/anaconda3/envs/mlproj/lib/python3.8/site-packages/keras/engine/training.py", line 2169, in predict_function  *
        return step_function(self, iterator)
    File "/opt/anaconda3/envs/mlproj/lib/python3.8/site-packages/keras/engine/training.py", line 2155, in step_function  **
        outputs = model.distribute_strategy.run(run_step, args=(data,))
    File "/opt/anaconda3/envs/mlproj/lib/python3.8/site-packages/keras/engine/training.py", line 2143, in run_step  **
        outputs = model.predict_step(data)
    File "/opt/anaconda3/envs/mlproj/lib/python3.8/site-packages/keras/engine/training.py", line 2111, in predict_step
        return self(x, training=False)
    File "/opt/anaconda3/envs/mlproj/lib/python3.8/site-packages/keras/utils/traceback_utils.py", line 70, in error_handler
        raise e.with_traceback(filtered_tb) from None
    File "/opt/anaconda3/envs/mlproj/lib/python3.8/site-packages/keras/engine/input_spec.py", line 298, in assert_input_compatibility
        raise ValueError(

    ValueError: Input 0 of layer "model" is incompatible with the layer: expected shape=(None, 224, 224, 3), found shape=(None, 224, 224, 4)

[2024-07-07 06:26:36,275: INFO: _internal: 127.0.0.1 - - [07/Jul/2024 06:26:36] "[35m[1mPOST /process_image HTTP/1.1[0m" 500 -]
[2024-07-07 06:28:13,254: INFO: _internal: [31m[1mWARNING: This is a development server. Do not use it in a production deployment. Use a production WSGI server instead.[0m
 * Running on all addresses (0.0.0.0)
 * Running on http://127.0.0.1:8080
 * Running on http://192.168.186.236:8080]
[2024-07-07 06:28:13,254: INFO: _internal: [33mPress CTRL+C to quit[0m]
[2024-07-07 06:28:21,845: INFO: _internal: 127.0.0.1 - - [07/Jul/2024 06:28:21] "GET / HTTP/1.1" 200 -]
[2024-07-07 06:28:21,921: INFO: _internal: 127.0.0.1 - - [07/Jul/2024 06:28:21] "[36mGET /static/css/style.css HTTP/1.1[0m" 304 -]
[2024-07-07 06:28:21,925: INFO: _internal: 127.0.0.1 - - [07/Jul/2024 06:28:21] "[36mGET /static/js/app.js HTTP/1.1[0m" 304 -]
[2024-07-07 06:28:36,638: ERROR: app: Exception on /process_image [POST]]
Traceback (most recent call last):
  File "/opt/anaconda3/envs/mlproj/lib/python3.8/site-packages/flask/app.py", line 2190, in wsgi_app
    response = self.full_dispatch_request()
  File "/opt/anaconda3/envs/mlproj/lib/python3.8/site-packages/flask/app.py", line 1486, in full_dispatch_request
    rv = self.handle_user_exception(e)
  File "/opt/anaconda3/envs/mlproj/lib/python3.8/site-packages/flask_cors/extension.py", line 178, in wrapped_function
    return cors_after_request(app.make_response(f(*args, **kwargs)))
  File "/opt/anaconda3/envs/mlproj/lib/python3.8/site-packages/flask/app.py", line 1484, in full_dispatch_request
    rv = self.dispatch_request()
  File "/opt/anaconda3/envs/mlproj/lib/python3.8/site-packages/flask/app.py", line 1469, in dispatch_request
    return self.ensure_sync(self.view_functions[rule.endpoint])(**view_args)
  File "/opt/anaconda3/envs/mlproj/lib/python3.8/site-packages/flask_cors/decorator.py", line 130, in wrapped_function
    resp = make_response(f(*args, **kwargs))
  File "app.py", line 49, in process_image
    result = np.argmax(model.predict(img_array), axis=1)
  File "/opt/anaconda3/envs/mlproj/lib/python3.8/site-packages/keras/utils/traceback_utils.py", line 70, in error_handler
    raise e.with_traceback(filtered_tb) from None
  File "/var/folders/_n/ppng6yzd1vb0pk3s230rdd540000gp/T/__autograph_generated_fileknexpph_.py", line 15, in tf__predict_function
    retval_ = ag__.converted_call(ag__.ld(step_function), (ag__.ld(self), ag__.ld(iterator)), None, fscope)
ValueError: in user code:

    File "/opt/anaconda3/envs/mlproj/lib/python3.8/site-packages/keras/engine/training.py", line 2169, in predict_function  *
        return step_function(self, iterator)
    File "/opt/anaconda3/envs/mlproj/lib/python3.8/site-packages/keras/engine/training.py", line 2155, in step_function  **
        outputs = model.distribute_strategy.run(run_step, args=(data,))
    File "/opt/anaconda3/envs/mlproj/lib/python3.8/site-packages/keras/engine/training.py", line 2143, in run_step  **
        outputs = model.predict_step(data)
    File "/opt/anaconda3/envs/mlproj/lib/python3.8/site-packages/keras/engine/training.py", line 2111, in predict_step
        return self(x, training=False)
    File "/opt/anaconda3/envs/mlproj/lib/python3.8/site-packages/keras/utils/traceback_utils.py", line 70, in error_handler
        raise e.with_traceback(filtered_tb) from None
    File "/opt/anaconda3/envs/mlproj/lib/python3.8/site-packages/keras/engine/input_spec.py", line 298, in assert_input_compatibility
        raise ValueError(

    ValueError: Input 0 of layer "model" is incompatible with the layer: expected shape=(None, 224, 224, 3), found shape=(None, 224, 224, 4)

[2024-07-07 06:28:36,643: INFO: _internal: 127.0.0.1 - - [07/Jul/2024 06:28:36] "[35m[1mPOST /process_image HTTP/1.1[0m" 500 -]
[2024-07-07 06:31:48,728: INFO: _internal: [31m[1mWARNING: This is a development server. Do not use it in a production deployment. Use a production WSGI server instead.[0m
 * Running on all addresses (0.0.0.0)
 * Running on http://127.0.0.1:8080
 * Running on http://192.168.186.236:8080]
[2024-07-07 06:31:48,728: INFO: _internal: [33mPress CTRL+C to quit[0m]
[2024-07-07 06:32:01,043: INFO: _internal: 127.0.0.1 - - [07/Jul/2024 06:32:01] "GET / HTTP/1.1" 200 -]
[2024-07-07 06:32:01,130: INFO: _internal: 127.0.0.1 - - [07/Jul/2024 06:32:01] "[36mGET /static/css/style.css HTTP/1.1[0m" 304 -]
[2024-07-07 06:32:01,134: INFO: _internal: 127.0.0.1 - - [07/Jul/2024 06:32:01] "[36mGET /static/js/app.js HTTP/1.1[0m" 304 -]
[2024-07-07 06:32:13,792: ERROR: app: Exception on /process_image [POST]]
Traceback (most recent call last):
  File "/opt/anaconda3/envs/mlproj/lib/python3.8/site-packages/flask/app.py", line 2190, in wsgi_app
    response = self.full_dispatch_request()
  File "/opt/anaconda3/envs/mlproj/lib/python3.8/site-packages/flask/app.py", line 1486, in full_dispatch_request
    rv = self.handle_user_exception(e)
  File "/opt/anaconda3/envs/mlproj/lib/python3.8/site-packages/flask_cors/extension.py", line 178, in wrapped_function
    return cors_after_request(app.make_response(f(*args, **kwargs)))
  File "/opt/anaconda3/envs/mlproj/lib/python3.8/site-packages/flask/app.py", line 1484, in full_dispatch_request
    rv = self.dispatch_request()
  File "/opt/anaconda3/envs/mlproj/lib/python3.8/site-packages/flask/app.py", line 1469, in dispatch_request
    return self.ensure_sync(self.view_functions[rule.endpoint])(**view_args)
  File "/opt/anaconda3/envs/mlproj/lib/python3.8/site-packages/flask_cors/decorator.py", line 130, in wrapped_function
    resp = make_response(f(*args, **kwargs))
  File "app.py", line 49, in process_image
    result = np.argmax(model.predict(img_array), axis=1)
  File "/opt/anaconda3/envs/mlproj/lib/python3.8/site-packages/keras/utils/traceback_utils.py", line 70, in error_handler
    raise e.with_traceback(filtered_tb) from None
  File "/var/folders/_n/ppng6yzd1vb0pk3s230rdd540000gp/T/__autograph_generated_fileqs88nccs.py", line 15, in tf__predict_function
    retval_ = ag__.converted_call(ag__.ld(step_function), (ag__.ld(self), ag__.ld(iterator)), None, fscope)
ValueError: in user code:

    File "/opt/anaconda3/envs/mlproj/lib/python3.8/site-packages/keras/engine/training.py", line 2169, in predict_function  *
        return step_function(self, iterator)
    File "/opt/anaconda3/envs/mlproj/lib/python3.8/site-packages/keras/engine/training.py", line 2155, in step_function  **
        outputs = model.distribute_strategy.run(run_step, args=(data,))
    File "/opt/anaconda3/envs/mlproj/lib/python3.8/site-packages/keras/engine/training.py", line 2143, in run_step  **
        outputs = model.predict_step(data)
    File "/opt/anaconda3/envs/mlproj/lib/python3.8/site-packages/keras/engine/training.py", line 2111, in predict_step
        return self(x, training=False)
    File "/opt/anaconda3/envs/mlproj/lib/python3.8/site-packages/keras/utils/traceback_utils.py", line 70, in error_handler
        raise e.with_traceback(filtered_tb) from None
    File "/opt/anaconda3/envs/mlproj/lib/python3.8/site-packages/keras/engine/input_spec.py", line 298, in assert_input_compatibility
        raise ValueError(

    ValueError: Input 0 of layer "model" is incompatible with the layer: expected shape=(None, 224, 224, 3), found shape=(None, 224, 224, 4)

[2024-07-07 06:32:13,798: INFO: _internal: 127.0.0.1 - - [07/Jul/2024 06:32:13] "[35m[1mPOST /process_image HTTP/1.1[0m" 500 -]
[2024-07-07 06:47:38,258: INFO: _internal: [31m[1mWARNING: This is a development server. Do not use it in a production deployment. Use a production WSGI server instead.[0m
 * Running on all addresses (0.0.0.0)
 * Running on http://127.0.0.1:8080
 * Running on http://192.168.186.236:8080]
[2024-07-07 06:47:38,259: INFO: _internal: [33mPress CTRL+C to quit[0m]
[2024-07-07 06:47:50,470: INFO: _internal: 127.0.0.1 - - [07/Jul/2024 06:47:50] "GET / HTTP/1.1" 200 -]
[2024-07-07 06:47:50,610: INFO: _internal: 127.0.0.1 - - [07/Jul/2024 06:47:50] "[36mGET /static/js/app.js HTTP/1.1[0m" 304 -]
[2024-07-07 06:47:50,631: INFO: _internal: 127.0.0.1 - - [07/Jul/2024 06:47:50] "[36mGET /static/css/style.css HTTP/1.1[0m" 304 -]
[2024-07-07 06:48:00,916: INFO: _internal: 127.0.0.1 - - [07/Jul/2024 06:48:00] "GET / HTTP/1.1" 200 -]
[2024-07-07 06:48:02,023: INFO: _internal: 127.0.0.1 - - [07/Jul/2024 06:48:02] "[36mGET /static/css/style.css HTTP/1.1[0m" 304 -]
[2024-07-07 06:48:02,035: INFO: _internal: 127.0.0.1 - - [07/Jul/2024 06:48:02] "[36mGET /static/js/app.js HTTP/1.1[0m" 304 -]
[2024-07-07 06:48:16,392: ERROR: app: Exception on /process_image [POST]]
Traceback (most recent call last):
  File "/opt/anaconda3/envs/mlproj/lib/python3.8/site-packages/flask/app.py", line 2190, in wsgi_app
    response = self.full_dispatch_request()
  File "/opt/anaconda3/envs/mlproj/lib/python3.8/site-packages/flask/app.py", line 1486, in full_dispatch_request
    rv = self.handle_user_exception(e)
  File "/opt/anaconda3/envs/mlproj/lib/python3.8/site-packages/flask_cors/extension.py", line 178, in wrapped_function
    return cors_after_request(app.make_response(f(*args, **kwargs)))
  File "/opt/anaconda3/envs/mlproj/lib/python3.8/site-packages/flask/app.py", line 1484, in full_dispatch_request
    rv = self.dispatch_request()
  File "/opt/anaconda3/envs/mlproj/lib/python3.8/site-packages/flask/app.py", line 1469, in dispatch_request
    return self.ensure_sync(self.view_functions[rule.endpoint])(**view_args)
  File "/opt/anaconda3/envs/mlproj/lib/python3.8/site-packages/flask_cors/decorator.py", line 130, in wrapped_function
    resp = make_response(f(*args, **kwargs))
  File "app.py", line 49, in process_image
    result = np.argmax(model.predict(img_array), axis=1)
  File "/opt/anaconda3/envs/mlproj/lib/python3.8/site-packages/keras/utils/traceback_utils.py", line 70, in error_handler
    raise e.with_traceback(filtered_tb) from None
  File "/var/folders/_n/ppng6yzd1vb0pk3s230rdd540000gp/T/__autograph_generated_file3qcuiw9l.py", line 15, in tf__predict_function
    retval_ = ag__.converted_call(ag__.ld(step_function), (ag__.ld(self), ag__.ld(iterator)), None, fscope)
ValueError: in user code:

    File "/opt/anaconda3/envs/mlproj/lib/python3.8/site-packages/keras/engine/training.py", line 2169, in predict_function  *
        return step_function(self, iterator)
    File "/opt/anaconda3/envs/mlproj/lib/python3.8/site-packages/keras/engine/training.py", line 2155, in step_function  **
        outputs = model.distribute_strategy.run(run_step, args=(data,))
    File "/opt/anaconda3/envs/mlproj/lib/python3.8/site-packages/keras/engine/training.py", line 2143, in run_step  **
        outputs = model.predict_step(data)
    File "/opt/anaconda3/envs/mlproj/lib/python3.8/site-packages/keras/engine/training.py", line 2111, in predict_step
        return self(x, training=False)
    File "/opt/anaconda3/envs/mlproj/lib/python3.8/site-packages/keras/utils/traceback_utils.py", line 70, in error_handler
        raise e.with_traceback(filtered_tb) from None
    File "/opt/anaconda3/envs/mlproj/lib/python3.8/site-packages/keras/engine/input_spec.py", line 298, in assert_input_compatibility
        raise ValueError(

    ValueError: Input 0 of layer "model" is incompatible with the layer: expected shape=(None, 224, 224, 3), found shape=(None, 224, 224, 4)

[2024-07-07 06:48:16,399: INFO: _internal: 127.0.0.1 - - [07/Jul/2024 06:48:16] "[35m[1mPOST /process_image HTTP/1.1[0m" 500 -]
[2024-07-07 07:19:05,682: INFO: _internal: [31m[1mWARNING: This is a development server. Do not use it in a production deployment. Use a production WSGI server instead.[0m
 * Running on all addresses (0.0.0.0)
 * Running on http://127.0.0.1:8080
 * Running on http://172.20.10.6:8080]
[2024-07-07 07:19:05,682: INFO: _internal: [33mPress CTRL+C to quit[0m]
[2024-07-07 07:19:21,063: INFO: _internal: 127.0.0.1 - - [07/Jul/2024 07:19:21] "GET / HTTP/1.1" 200 -]
[2024-07-07 07:19:21,125: INFO: _internal: 127.0.0.1 - - [07/Jul/2024 07:19:21] "[36mGET /static/css/style.css HTTP/1.1[0m" 304 -]
[2024-07-07 07:19:21,160: INFO: _internal: 127.0.0.1 - - [07/Jul/2024 07:19:21] "[36mGET /static/js/app.js HTTP/1.1[0m" 304 -]
[2024-07-07 07:19:29,509: INFO: _internal: 127.0.0.1 - - [07/Jul/2024 07:19:29] "[36mGET /static/css/style.css HTTP/1.1[0m" 304 -]
[2024-07-07 07:19:48,054: INFO: _internal: 127.0.0.1 - - [07/Jul/2024 07:19:48] "POST /process_image HTTP/1.1" 200 -]
[2024-07-07 07:20:18,006: INFO: _internal: 127.0.0.1 - - [07/Jul/2024 07:20:18] "POST /process_image HTTP/1.1" 200 -]
[2024-07-07 07:29:07,231: INFO: _internal: 127.0.0.1 - - [07/Jul/2024 07:29:07] "GET / HTTP/1.1" 200 -]
[2024-07-07 07:29:07,410: INFO: _internal: 127.0.0.1 - - [07/Jul/2024 07:29:07] "GET /static/js/app.js HTTP/1.1" 200 -]
[2024-07-07 07:29:07,448: INFO: _internal: 127.0.0.1 - - [07/Jul/2024 07:29:07] "GET /static/css/style.css HTTP/1.1" 200 -]
[2024-07-07 07:29:31,580: INFO: _internal: [31m[1mWARNING: This is a development server. Do not use it in a production deployment. Use a production WSGI server instead.[0m
 * Running on all addresses (0.0.0.0)
 * Running on http://127.0.0.1:8080
 * Running on http://172.20.10.6:8080]
[2024-07-07 07:29:31,581: INFO: _internal: [33mPress CTRL+C to quit[0m]
[2024-07-07 07:31:30,472: INFO: _internal: 127.0.0.1 - - [07/Jul/2024 07:31:30] "GET / HTTP/1.1" 200 -]
[2024-07-07 07:31:30,574: INFO: _internal: 127.0.0.1 - - [07/Jul/2024 07:31:30] "[36mGET /static/css/style.css HTTP/1.1[0m" 304 -]
[2024-07-07 07:31:30,583: INFO: _internal: 127.0.0.1 - - [07/Jul/2024 07:31:30] "[36mGET /static/js/app.js HTTP/1.1[0m" 304 -]
[2024-07-07 07:31:44,978: INFO: _internal: 127.0.0.1 - - [07/Jul/2024 07:31:44] "GET / HTTP/1.1" 200 -]
[2024-07-07 07:31:45,047: INFO: _internal: 127.0.0.1 - - [07/Jul/2024 07:31:45] "[36mGET /static/css/style.css HTTP/1.1[0m" 304 -]
[2024-07-07 07:31:45,048: INFO: _internal: 127.0.0.1 - - [07/Jul/2024 07:31:45] "[36mGET /static/js/app.js HTTP/1.1[0m" 304 -]
[2024-07-07 07:33:10,783: INFO: _internal: 127.0.0.1 - - [07/Jul/2024 07:33:10] "GET / HTTP/1.1" 200 -]
[2024-07-07 07:33:10,821: INFO: _internal: 127.0.0.1 - - [07/Jul/2024 07:33:10] "[36mGET /static/css/style.css HTTP/1.1[0m" 304 -]
[2024-07-07 07:33:10,828: INFO: _internal: 127.0.0.1 - - [07/Jul/2024 07:33:10] "[36mGET /static/js/app.js HTTP/1.1[0m" 304 -]
[2024-07-07 07:33:14,198: INFO: _internal: 127.0.0.1 - - [07/Jul/2024 07:33:14] "GET / HTTP/1.1" 200 -]
[2024-07-07 07:33:14,221: INFO: _internal: 127.0.0.1 - - [07/Jul/2024 07:33:14] "[36mGET /static/css/style.css HTTP/1.1[0m" 304 -]
[2024-07-07 07:33:14,224: INFO: _internal: 127.0.0.1 - - [07/Jul/2024 07:33:14] "[36mGET /static/js/app.js HTTP/1.1[0m" 304 -]
[2024-07-07 07:33:28,980: INFO: _internal: 127.0.0.1 - - [07/Jul/2024 07:33:28] "POST /process_image HTTP/1.1" 200 -]
[2024-07-07 07:34:28,155: INFO: _internal: 127.0.0.1 - - [07/Jul/2024 07:34:28] "POST /process_image HTTP/1.1" 200 -]
[2024-07-07 07:34:34,439: INFO: _internal: 127.0.0.1 - - [07/Jul/2024 07:34:34] "GET / HTTP/1.1" 200 -]
[2024-07-07 07:34:34,517: INFO: _internal: 127.0.0.1 - - [07/Jul/2024 07:34:34] "[36mGET /static/css/style.css HTTP/1.1[0m" 304 -]
[2024-07-07 07:34:34,522: INFO: _internal: 127.0.0.1 - - [07/Jul/2024 07:34:34] "[36mGET /static/js/app.js HTTP/1.1[0m" 304 -]
[2024-07-07 07:38:49,851: INFO: _internal: 127.0.0.1 - - [07/Jul/2024 07:38:49] "GET / HTTP/1.1" 200 -]
[2024-07-07 07:38:49,937: INFO: _internal: 127.0.0.1 - - [07/Jul/2024 07:38:49] "[36mGET /static/css/style.css HTTP/1.1[0m" 304 -]
[2024-07-07 07:38:49,941: INFO: _internal: 127.0.0.1 - - [07/Jul/2024 07:38:49] "GET /static/js/app.js HTTP/1.1" 200 -]
[2024-07-07 07:39:37,100: INFO: _internal: 127.0.0.1 - - [07/Jul/2024 07:39:37] "POST /process_image HTTP/1.1" 200 -]
